<?xml version="1.0" encoding="utf-8"?>
<!-- This URDF was automatically created by SolidWorks to URDF Exporter! Originally created by Stephen Brawner (brawner@gmail.com) 
     Commit Version: 1.6.0-1-g15f4949  Build Version: 1.6.7594.29634
     For more information, please see http://wiki.ros.org/sw_urdf_exporter -->
<robot
  name="Hand Assembly_URDF">
  <link
    name="Palm">
    <inertial>
      <origin
        xyz="0.00542702034628404 -0.0153261828960426 -0.00331775831735218"
        rpy="0 0 0" />
      <mass
        value="0.12595408931589" />
      <inertia
        ixx="5.33078079883839E-05"
        ixy="6.80968134351283E-07"
        ixz="-7.95409066394676E-06"
        iyy="0.000121852360840743"
        iyz="-1.56774052583154E-06"
        izz="0.000126417743584675" />
    </inertial>
    <visual>
      <origin
        xyz="0 0 0"
        rpy="0 0 0" />
      <geometry>
        <mesh
          filename="ruka/meshes/Palm.STL" />
      </geometry>
      <material
        name="">
        <color
          rgba="0.43921568627451 0.474509803921569 0.501960784313725 1" />
      </material>
    </visual>
    <collision>
      <origin
        xyz="0 0 0"
        rpy="0 0 0" />
      <geometry>
        <mesh
          filename="ruka/meshes/Palm.STL" />
      </geometry>
    </collision>
  </link>
  <link
    name="Index_MCP_Link">
    <inertial>
      <origin
        xyz="0.0288723846218028 -1.28992836481712E-08 0.00378475045602162"
        rpy="0 0 0" />
      <mass
        value="0.00327912415799064" />
      <inertia
        ixx="1.41290464856069E-07"
        ixy="2.3268258803478E-15"
        ixz="-8.23139112924128E-10"
        iyy="3.58573756788115E-07"
        iyz="5.12742103479596E-14"
        izz="4.20814642779602E-07" />
    </inertial>
    <visual>
      <origin
        xyz="-0.046 0.005 -0.003"
        rpy="0 0 0" />
      <geometry>
        <mesh
          filename="ruka/meshes/Index_MCP.STL" />
      </geometry>
      <material
        name="">
        <color
          rgba="0.43921568627451 0.474509803921569 0.501960784313725 1" />
      </material>
    </visual>
    <collision>
      <origin
        xyz="-0.046 0.005 -0.003"
        rpy="0 0 0" />
      <geometry>
        <mesh
          filename="ruka/meshes/Index_MCP.STL" />
      </geometry>
    </collision>
  </link>
  <joint
    name="Index_MCP_Joint"
    type="revolute">
    <origin
      xyz="0.0322 0.0146007 -0.08022"
      rpy="2.5326 -1.3601 2.1257" />
    <parent
      link="Palm" />
    <child
      link="Index_MCP_Link" />
    <axis
      xyz="0 1 0" />
    <limit
      lower="0"
      upper="2.44222"
      effort="1"
      velocity="1" />
  </joint>
  <link
    name="Index_DIP_Link">
    <inertial>
      <origin
        xyz="0.000734413748040258 -1.34435329920274E-07 0.00333493475378864"
        rpy="0 0 0" />
      <mass
        value="0.00300529600906836" />
      <inertia
        ixx="9.14347124492149E-08"
        ixy="6.87460618871933E-13"
        ixz="9.51049053465791E-09"
        iyy="2.50136052110671E-07"
        iyz="-9.0601934678023E-13"
        izz="2.7749019855714E-07" />
    </inertial>
    <visual>
      <origin
        xyz="-0.012 0.005 -0.003"
        rpy="0 0 0" />
      <geometry>
        <mesh
          filename="ruka/meshes/Index_DIP.STL" />
      </geometry>
      <material
        name="">
        <color
          rgba="0.43921568627451 0.474509803921569 0.501960784313725 1" />
      </material>
    </visual>
    <collision>
      <origin
        xyz="-0.012 0.005 -0.003"
        rpy="0 0 0" />
      <geometry>
        <mesh
          filename="ruka/meshes/Index_DIP.STL" />
      </geometry>
    </collision>
  </link>
  <joint
    name="Index_DIP_Joint"
    type="revolute">
    <origin
      xyz="-0.035057 0 0.002"
      rpy="0 0.17453 0" />
    <parent
      link="Index_MCP_Link" />
    <child
      link="Index_DIP_Link" />
    <axis
      xyz="0 1 0" />
    <limit
      lower="0"
      upper="2.09"
      effort="1"
      velocity="1" />
  </joint>
  <link
    name="Index_PIP_Link">
    <inertial>
      <origin
        xyz="-0.0274082864999729 1.00210984628479E-07 0.00320314184184918"
        rpy="0 0 0" />
      <mass
        value="0.00356976709245697" />
      <inertia
        ixx="1.11979347030368E-07"
        ixy="1.89132850331097E-12"
        ixz="-1.23407955200532E-08"
        iyy="2.91756149799755E-07"
        iyz="8.4756428845289E-13"
        izz="3.32126996846302E-07" />
    </inertial>
    <visual>
      <origin
        xyz="0.013 0.0004 -0.005"
        rpy="0 0 0" />
      <geometry>
        <mesh
          filename="ruka/meshes/Index_PIP.STL" />
      </geometry>
      <material
        name="">
        <color
          rgba="0.43921568627451 0.474509803921569 0.501960784313725 1" />
      </material>
    </visual>
    <collision>
      <origin
        xyz="0.013 0.0004 -0.005"
        rpy="0 0 0" />
      <geometry>
        <mesh
          filename="ruka/meshes/Index_PIP.STL" />
      </geometry>
    </collision>
  </link>
  <joint
    name="Index_PIP_Joint"
    type="revolute">
    <origin
      xyz="-0.027 0.0045 0.001"
      rpy="0 0 0" />
    <parent
      link="Index_DIP_Link" />
    <child
      link="Index_PIP_Link" />
    <axis
      xyz="0 1 0" />
    <limit
      lower="0"
      upper="2.09"
      effort="1"
      velocity="1" />
  </joint>
  <link
    name="Middle_MCP_Link">
    <inertial>
      <origin
        xyz="0.0288723883673292 -9.49407751894837E-09 0.00378477344579253"
        rpy="0 0 0" />
      <mass
        value="0.00327911243246083" />
      <inertia
        ixx="1.41289936523514E-07"
        ixy="7.30667671947528E-14"
        ixz="-8.22938282805633E-10"
        iyy="3.58571786982875E-07"
        iyz="7.19973200752265E-14"
        izz="4.20812624879611E-07" />
    </inertial>
    <visual>
      <origin
        xyz="-0.046 0 -0.003"
        rpy="0 0 0" />
      <geometry>
        <mesh
          filename="ruka/meshes/Middle_MCP.STL" />
      </geometry>
      <material
        name="">
        <color
          rgba="0.43921568627451 0.474509803921569 0.501960784313725 1" />
      </material>
    </visual>
    <collision>
      <origin
        xyz="-0.046 0 -0.003"
        rpy="0 0 0" />
      <geometry>
        <mesh
          filename="ruka/meshes/Middle_MCP.STL" />
      </geometry>
    </collision>
  </link>
  <joint
    name="Middle_MCP_Joint"
    type="revolute">
    <origin
      xyz="0.01518 0.0135414 -0.081"
      rpy="-1.57079632 -1.57079632 0" />
    <parent
      link="Palm" />
    <child
      link="Middle_MCP_Link" />
    <axis
      xyz="0 1 0" />
    <limit
      lower="0"
      upper="2.44222"
      effort="1"
      velocity="1" />
  </joint>
  <link
    name="Middle_DIP_Link">
    <inertial>
      <origin
        xyz="0.000734411874024732 -1.31356892699858E-07 0.00333493692396733"
        rpy="0 0 0" />
      <mass
        value="0.0030052951603588" />
      <inertia
        ixx="9.14347535880294E-08"
        ixy="7.13882426711299E-13"
        ixz="9.51040830783885E-09"
        iyy="2.50135897841292E-07"
        iyz="-9.47555003073026E-13"
        izz="2.77490105957776E-07" />
    </inertial>
    <visual>
      <origin
        xyz="-0.012 0 -0.003"
        rpy="0 0 0" />
      <geometry>
        <mesh
          filename="ruka/meshes/Middle_DIP.STL" />
      </geometry>
      <material
        name="">
        <color
          rgba="0.43921568627451 0.474509803921569 0.501960784313725 1" />
      </material>
    </visual>
    <collision>
      <origin
        xyz="-0.012 0 -0.003"
        rpy="0 0 0" />
      <geometry>
        <mesh
          filename="ruka/meshes/Middle_DIP.STL" />
      </geometry>
    </collision>
  </link>
  <joint
    name="Middle_DIP_Joint"
    type="revolute">
    <origin
      xyz="-0.034 0 0"
      rpy="0 0 0" />
    <parent
      link="Middle_MCP_Link" />
    <child
      link="Middle_DIP_Link" />
    <axis
      xyz="0 1 0" />
    <limit
      lower="0"
      upper="2.09"
      effort="1"
      velocity="1" />
  </joint>
  <link
    name="Middle_PIP_Link">
    <inertial>
      <origin
        xyz="-0.0274082879981569 9.97468629377468E-08 0.0032031423234857"
        rpy="0 0 0" />
      <mass
        value="0.0035697679495293" />
      <inertia
        ixx="1.11979304164007E-07"
        ixy="1.7216669734829E-12"
        ixz="-1.23407821598614E-08"
        iyy="2.91756255575108E-07"
        iyz="7.5604039766423E-13"
        izz="3.32127015597567E-07" />
    </inertial>
    <visual>
      <origin
        xyz="0.014 0 -0.0045"
        rpy="0 0 0" />
      <geometry>
        <mesh
          filename="ruka/meshes/Middle_PIP.STL" />
      </geometry>
      <material
        name="">
        <color
          rgba="0.43921568627451 0.474509803921569 0.501960784313725 1" />
      </material>
    </visual>
    <collision>
      <origin
        xyz="0.014 0 -0.0045"
        rpy="0 0 0" />
      <geometry>
        <mesh
          filename="ruka/meshes/Middle_PIP.STL" />
      </geometry>
    </collision>
  </link>
  <joint
    name="Middle_PIP_Joint"
    type="revolute">
    <origin
      xyz="-0.026 0 0.002"
      rpy="0 0 0" />
    <parent
      link="Middle_DIP_Link" />
    <child
      link="Middle_PIP_Link" />
    <axis
      xyz="0 1 0" />
    <limit
      lower="0"
      upper="2.09"
      effort="1"
      velocity="1" />
  </joint>
  <link
    name="Ring_MCP_Link">
    <inertial>
      <origin
        xyz="0.0288723878014377 -7.11557345358695E-09 0.00378475517527948"
        rpy="0 0 0" />
      <mass
        value="0.00327912106977147" />
      <inertia
        ixx="1.41290358756154E-07"
        ixy="9.2842233711606E-14"
        ixz="-8.23018832573341E-10"
        iyy="3.58573511962594E-07"
        iyz="9.22480523524179E-14"
        izz="4.20814347169238E-07" />
    </inertial>
    <visual>
      <origin
        xyz="-0.046 0 -0.004"
        rpy="0 0 0" />
      <geometry>
        <mesh
          filename="ruka/meshes/Ring_MCP.STL" />
      </geometry>
      <material
        name="">
        <color
          rgba="0.43921568627451 0.474509803921569 0.501960784313725 1" />
      </material>
    </visual>
    <collision>
      <origin
        xyz="-0.046 0 -0.004"
        rpy="0 0 0" />
      <geometry>
        <mesh
          filename="ruka/meshes/Ring_MCP.STL" />
      </geometry>
    </collision>
  </link>
  <joint
    name="Ring_MCP_Joint"
    type="revolute">
    <origin
      xyz="-0.0088 0.01453 -0.08009"
      rpy="-1.2806 -1.4598 -0.34861" />
    <parent
      link="Palm" />
    <child
      link="Ring_MCP_Link" />
    <axis
      xyz="0 1 0" />
    <limit
      lower="0"
      upper="2.44222"
      effort="1"
      velocity="1" />
  </joint>
  <link
    name="Ring_DIP_Link">
    <inertial>
      <origin
        xyz="0.000734408991983959 -1.2934669113172E-07 0.00333493923161951"
        rpy="0 0 0" />
      <mass
        value="0.00300529389020819" />
      <inertia
        ixx="9.14347671958401E-08"
        ixy="7.30508706208178E-13"
        ixz="9.51036963633025E-09"
        iyy="2.50135803853248E-07"
        iyz="-9.93138148031057E-13"
        izz="2.77490043515239E-07" />
    </inertial>
    <visual>
      <origin
        xyz="-0.01 0 -0.004"
        rpy="0 0 0" />
      <geometry>
        <mesh
          filename="ruka/meshes/Ring_DIP.STL" />
      </geometry>
      <material
        name="">
        <color
          rgba="0.43921568627451 0.474509803921569 0.501960784313725 1" />
      </material>
    </visual>
    <collision>
      <origin
        xyz="-0.01 0 -0.004"
        rpy="0 0 0" />
      <geometry>
        <mesh
          filename="ruka/meshes/Ring_DIP.STL" />
      </geometry>
    </collision>
  </link>
  <joint
    name="Ring_DIP_Joint"
    type="revolute">
    <origin
      xyz="-0.036 0 0"
      rpy="0 0 0" />
    <parent
      link="Ring_MCP_Link" />
    <child
      link="Ring_DIP_Link" />
    <axis
      xyz="0 1 0" />
    <limit
      lower="0"
      upper="2.09"
      effort="1"
      velocity="1" />
  </joint>
  <link
    name="Ring_PIP_Link">
    <inertial>
      <origin
        xyz="-0.02740827895642 1.00945133223911E-07 0.00320314931394115"
        rpy="0 0 0" />
      <mass
        value="0.00356976241817527" />
      <inertia
        ixx="1.11979151950286E-07"
        ixy="1.6521472387838E-12"
        ixz="-1.23402406165857E-08"
        iyy="2.91755752392006E-07"
        iyz="7.13174165022662E-13"
        izz="3.3212644786114E-07" />
    </inertial>
    <visual>
      <origin
        xyz="0.015 0 -0.005"
        rpy="0 0 0" />
      <geometry>
        <mesh
          filename="ruka/meshes/Ring_PIP.STL" />
      </geometry>
      <material
        name="">
        <color
          rgba="0.43921568627451 0.474509803921569 0.501960784313725 1" />
      </material>
    </visual>
    <collision>
      <origin
        xyz="0.015 0 -0.005"
        rpy="0 0 0" />
      <geometry>
        <mesh
          filename="ruka/meshes/Ring_PIP.STL" />
      </geometry>
    </collision>
  </link>
  <joint
    name="Ring_PIP_Joint"
    type="revolute">
    <origin
      xyz="-0.025746 0 0"
      rpy="0 0 0" />
    <parent
      link="Ring_DIP_Link" />
    <child
      link="Ring_PIP_Link" />
    <axis
      xyz="0 1 0" />
    <limit
      lower="0"
      upper="2.09"
      effort="1"
      velocity="1" />
  </joint>
  <link
    name="Pinky_MCP_Link">
    <inertial>
      <origin
        xyz="0.0268917272607511 -2.13280075440914E-08 0.00337656502783252"
        rpy="0 0 0" />
      <mass
        value="0.00308278515475546" />
      <inertia
        ixx="1.30752461776406E-07"
        ixy="1.67654854860561E-12"
        ixz="2.08816071197579E-09"
        iyy="3.3147641614642E-07"
        iyz="-1.05409730185614E-13"
        izz="3.86700640520072E-07" />
    </inertial>
    <visual>
      <origin
        xyz="-0.042 0 -0.004"
        rpy="0 0 0" />
      <geometry>
        <mesh
          filename="ruka/meshes/Pinky_MCP.STL" />
      </geometry>
      <material
        name="">
        <color
          rgba="0.43921568627451 0.474509803921569 0.501960784313725 1" />
      </material>
    </visual>
    <collision>
      <origin
        xyz="-0.042 0 -0.004"
        rpy="0 0 0" />
      <geometry>
        <mesh
          filename="ruka/meshes/Pinky_MCP.STL" />
      </geometry>
    </collision>
  </link>
  <joint
    name="Pinky_MCP_Joint"
    type="revolute">
    <origin
      xyz="-0.030617 0.020313 -0.07398"
      rpy="-1.1404 -1.3618 -0.5566" />
    <parent
      link="Palm" />
    <child
      link="Pinky_MCP_Link" />
    <axis
      xyz="0 1 0" />
    <limit
      lower="0"
      upper="2.44222"
      effort="1"
      velocity="1" />
  </joint>
  <link
    name="Pinky_DIP_Link">
    <inertial>
      <origin
        xyz="0.000757211877111238 -1.38277174707019E-07 0.00329942828313"
        rpy="0 0 0" />
      <mass
        value="0.00260945166429854" />
      <inertia
        ixx="7.77156460083423E-08"
        ixy="6.26394322619672E-13"
        ixz="8.13314389666295E-09"
        iyy="1.89485121914151E-07"
        iyz="-9.9417292970972E-13"
        izz="2.12042345602203E-07" />
    </inertial>
    <visual>
      <origin
        xyz="-0.01 0 -0.0037"
        rpy="0 0 0" />
      <geometry>
        <mesh
          filename="ruka/meshes/Pinky_DIP.STL" />
      </geometry>
      <material
        name="">
        <color
          rgba="0.43921568627451 0.474509803921569 0.501960784313725 1" />
      </material>
    </visual>
    <collision>
      <origin
        xyz="-0.01 0 -0.0037"
        rpy="0 0 0" />
      <geometry>
        <mesh
          filename="ruka/meshes/Pinky_DIP.STL" />
      </geometry>
    </collision>
  </link>
  <joint
    name="Pinky_DIP_Joint"
    type="revolute">
    <origin
      xyz="-0.032 0 0"
      rpy="0 0.027735 0" />
    <parent
      link="Pinky_MCP_Link" />
    <child
      link="Pinky_DIP_Link" />
    <axis
      xyz="0 1 0" />
    <limit
      lower="0"
      upper="2.09"
      effort="1"
      velocity="1" />
  </joint>
  <link
    name="Pinky_PIP_Link">
    <inertial>
      <origin
        xyz="-0.0236575116359834 -8.70957672025052E-08 0.00338829472701592"
        rpy="0 0 0" />
      <mass
        value="0.0030687510852178" />
      <inertia
        ixx="9.65855213707718E-08"
        ixy="1.45544365202047E-12"
        ixz="-6.92866969498395E-09"
        iyy="1.96147432047684E-07"
        iyz="-2.61547739439292E-13"
        izz="2.30492461614567E-07" />
    </inertial>
    <visual>
      <origin
        xyz="0.013 0 -0.005"
        rpy="0 0 0" />
      <geometry>
        <mesh
          filename="ruka/meshes/Pinky_PIP.STL" />
      </geometry>
      <material
        name="">
        <color
          rgba="0.43921568627451 0.474509803921569 0.501960784313725 1" />
      </material>
    </visual>
    <collision>
      <origin
        xyz="0.013 0 -0.005"
        rpy="0 0 0" />
      <geometry>
        <mesh
          filename="ruka/meshes/Pinky_PIP.STL" />
      </geometry>
    </collision>
  </link>
  <joint
    name="Pinky_PIP_Joint"
    type="revolute">
    <origin
      xyz="-0.023 0 0.001"
      rpy="0 0 0" />
    <parent
      link="Pinky_DIP_Link" />
    <child
      link="Pinky_PIP_Link" />
    <axis
      xyz="0 1 0" />
    <limit
      lower="0"
      upper="2.09"
      effort="1"
      velocity="1" />
  </joint>
  <link
    name="Thumb_MCP_Link">
    <inertial>
      <origin
        xyz="0.0162525772945904 -0.00468252056075796 0.00333968865411333"
        rpy="0 0 0" />
      <mass
        value="0.00526715244868984" />
      <inertia
        ixx="3.78342666091296E-07"
        ixy="3.45355822348593E-09"
        ixz="5.79256748472346E-08"
        iyy="5.49214507144661E-07"
        iyz="1.80637473136555E-10"
        izz="7.4416515368945E-07" />
    </inertial>
    <visual>
      <origin
        xyz="0 0 -0.007"
        rpy="0 0 0" />
      <geometry>
        <mesh
          filename="ruka/meshes/Thumb_MCP.STL" />
      </geometry>
      <material
        name="">
        <color
          rgba="0.43921568627451 0.474509803921569 0.501960784313725 1" />
      </material>
    </visual>
    <collision>
      <origin
        xyz="0 0 -0.007"
        rpy="0 0 0" />
      <geometry>
        <mesh
          filename="ruka/meshes/Thumb_MCP.STL" />
      </geometry>
    </collision>
  </link>
  <joint
    name="Thumb_CMC_Joint"
    type="revolute">
    <origin
      xyz="0.037688 0.022225 -0.025118"
      rpy="-1.5708 0 0.031855" />
    <parent
      link="Palm" />
    <child
      link="Thumb_MCP_Link" />
    <axis
      xyz="0 -1 0" />
    <limit
      lower="0"
      upper="3.314"
      effort="1"
      velocity="1" />
  </joint>
  <link
    name="Thumb_DIP_Link">
    <inertial>
      <origin
        xyz="-0.000359156365804594 5.04339516718168E-05 0.00349653038903846"
        rpy="0 0 0" />
      <mass
        value="0.00330019814015192" />
      <inertia
        ixx="1.24638539338724E-07"
        ixy="-9.75202530037393E-10"
        ixz="2.30346568241183E-09"
        iyy="2.79541547860756E-07"
        iyz="5.24310792821024E-10"
        izz="3.34593641849097E-07" />
    </inertial>
    <visual>
      <origin
        xyz="-0.013 0 -0.0019"
        rpy="-0.8 0 0" />
      <geometry>
        <mesh
          filename="ruka/meshes/Thumb_DIP.STL" />
      </geometry>
      <material
        name="">
        <color
          rgba="0.43921568627451 0.474509803921569 0.501960784313725 1" />
      </material>
    </visual>
    <collision>
      <origin
        xyz="-0.013 0 -0.0019"
        rpy="-0.8 0 0" />
      <geometry>
        <mesh
          filename="ruka/meshes/Thumb_DIP.STL" />
      </geometry>
    </collision>
  </link>
  <joint
    name="Thumb_MCP_Joint"
    type="revolute">
    <origin
      xyz="0.033935 -0.0044094 -0.0065999"
      rpy="1.57079 0 3.1416" />
    <parent
      link="Thumb_MCP_Link" />
    <child
      link="Thumb_DIP_Link" />
    <axis
      xyz="0 1 0" />
    <limit
      lower="0"
      upper="1.57"
      effort="1"
      velocity="1" />
  </joint>
  <link
    name="Thumb_PIP_Link">
    <inertial>
      <origin
        xyz="-0.028210435039398 -4.96887226884846E-08 0.00319436851781224"
        rpy="0 0 0" />
      <mass
        value="0.00347336056393131" />
      <inertia
        ixx="1.22784302245204E-07"
        ixy="-3.66847866115203E-12"
        ixz="-1.15065477781905E-08"
        iyy="2.59469354727498E-07"
        iyz="-3.44283087053825E-13"
        izz="3.11652173339995E-07" />
    </inertial>
    <visual>
      <origin
        xyz="0.015 0 -0.005"
        rpy="0 0 0" />
      <geometry>
        <mesh
          filename="ruka/meshes/Thumb_PIP.STL" />
      </geometry>
      <material
        name="">
        <color
          rgba="0.43921568627451 0.474509803921569 0.501960784313725 1" />
      </material>
    </visual>
    <collision>
      <origin
        xyz="0.015 0 -0.005"
        rpy="0 0 0" />
      <geometry>
        <mesh
          filename="ruka/meshes/Thumb_PIP.STL" />
      </geometry>
    </collision>
  </link>
  <joint
    name="Thumb_IP_Joint"
    type="revolute">
    <origin
      xyz="-0.027794 0.0035 0.000007"
      rpy="-0.7854 0 0" />
    <parent
      link="Thumb_DIP_Link" />
    <child
      link="Thumb_PIP_Link" />
    <axis
      xyz="0 1 0" />
    <limit
      lower="0"
      upper="2.09"
      effort="1"
      velocity="1" />
  </joint>


  <link name="index_actual_tip">
    <inertial>
      <mass value="0.001"/>
      <inertia ixx="0.001" ixy="0" ixz="0" iyy="0.001" iyz="0" izz="0.001"/>
    </inertial>
  </link>
  <joint name="index_actual_tip_joint" type="fixed">
    <parent link="Index_PIP_Link"/> 
    <child link="index_actual_tip"/>
    <origin xyz="-0. 0 -0" rpy="0 0 0"/>
  </joint>

  <link name="middle_actual_tip">
    <inertial>
      <mass value="0.001"/>
      <inertia ixx="0.001" ixy="0" ixz="0" iyy="0.001" iyz="0" izz="0.001"/>
    </inertial>
  </link>
  <joint name="middle_actual_tip_joint" type="fixed">
    <parent link="Middle_PIP_Link"/> 
    <child link="middle_actual_tip"/>
    <origin xyz="-0. 0.002 -0." rpy="0 0 0"/>
  </joint>

  <link name="ring_actual_tip">
    <inertial>
      <mass value="0.001"/>
      <inertia ixx="0.001" ixy="0" ixz="0" iyy="0.001" iyz="0" izz="0.001"/>
    </inertial>
  </link>
  <joint name="ring_actual_tip_joint" type="fixed">
    <parent link="Ring_PIP_Link"/> 
    <child link="ring_actual_tip"/>
    <origin xyz="-0.0 0.002 -0.0" rpy="0 0 0"/>
  </joint>

  <link name="pinky_actual_tip">
    <inertial>
      <mass value="0.001"/>
      <inertia ixx="0.001" ixy="0" ixz="0" iyy="0.001" iyz="0" izz="0.001"/>
    </inertial>
  </link>
  <joint name="pinky_actual_tip_joint" type="fixed">
    <parent link="Pinky_PIP_Link"/> 
    <child link="pinky_actual_tip"/>
    <origin xyz="-0.0 0.002 -0.0" rpy="0 0 0"/>
  </joint>

  <link name="thumb_actual_tip">
    <inertial>
      <mass value="0.001"/>
      <inertia ixx="0.001" ixy="0" ixz="0" iyy="0.001" iyz="0" izz="0.001"/>
    </inertial>
  </link>
  <joint name="thumb_actual_tip_joint" type="fixed">
    <parent link="Thumb_PIP_Link"/> 
    <child link="thumb_actual_tip"/>
    <origin xyz="-0.01 0.0 0.0057" rpy="0 0 0"/>
  </joint>
</robot>